Workbook

Sheet ELC_TRADE
A1: Trans - Insert
B2: ~TFM_INS
B3: TimeSlice | C3: LimType | D3: Attribute | E3: Year | F3: SE1 | G3: SE2 | H3: SE3 | I3: SE4 | J3: Pset_Set | K3: Pset_PN | L3: Pset_PD | M3: Pset_CI | N3: Pset_CO | O3: Cset_Set | P3: Cset_CN | Q3: Cset_CD
D4: EFF | E4: 2010 | F4: 0.98 | G4: =F4 -> 0.98 | H4: =F4 -> 0.98 | I4: =F4 -> 0.98 | K4: TB_ELCC_SE1_SE2_01
D5: EFF | E5: 2010 | F5: 0.98 | G5: =F5 -> 0.98 | H5: =F5 -> 0.98 | I5: =F5 -> 0.98 | K5: TB_ELCC_SE2_SE3_01
D6: EFF | E6: 2010 | F6: 0.98 | G6: =F6 -> 0.98 | H6: =F6 -> 0.98 | I6: =F6 -> 0.98 | K6: TB_ELCC_SE3_SE4_01
C7: FX | D7: CAP_BND | E7: 2010 | F7: 3300 | G7: 3300 | K7: TB_ELCC_SE1_SE2_01
C8: FX | D8: CAP_BND | E8: 2010 | G8: 7300 | H8: 7300 | K8: TB_ELCC_SE2_SE3_01
C9: FX | D9: CAP_BND | E9: 2010 | H9: 5300 | I9: 2000 | K9: TB_ELCC_SE3_SE4_01
C10: FX | D10: CAP_BND | E10: 2020 | F10: 3300 | G10: 3300 | K10: TB_ELCC_SE1_SE2_01
C11: FX | D11: CAP_BND | E11: 2020 | G11: 7300 | H11: 7300 | K11: TB_ELCC_SE2_SE3_01
C12: FX | D12: CAP_BND | E12: 2020 | H12: 5300 | I12: 2000 | K12: TB_ELCC_SE3_SE4_01
C13: UP | D13: CAP_BND | E13: 0 | F13: 5 | G13: =F13 -> 5 | H13: =F13 -> 5 | I13: =F13 -> 5 | K13: TB_ELCC_SE1_SE2_01
C14: UP | D14: CAP_BND | E14: 0 | F14: 5 | G14: =F14 -> 5 | H14: =F14 -> 5 | I14: =F14 -> 5 | K14: TB_ELCC_SE2_SE3_01
C15: UP | D15: CAP_BND | E15: 0 | F15: 5 | G15: =F15 -> 5 | H15: =F15 -> 5 | I15: =F15 -> 5 | K15: TB_ELCC_SE3_SE4_01
C16: UP | D16: CAP_BND | E16: 2030 | F16: ='Data New Transmission'!Y6 -> 3300 | G16: ='Data New Transmission'!Y6 -> 3300 | K16: TB_ELCC_SE1_SE2_01
C17: UP | D17: CAP_BND | E17: 2030 | G17: ='Data New Transmission'!Y7 -> 8700 | H17: ='Data New Transmission'!Y7 -> 8700 | K17: TB_ELCC_SE2_SE3_01
C18: UP | D18: CAP_BND | E18: 2030 | H18: ='Data New Transmission'!Y8 -> 7200 | I18: ='Data New Transmission'!Y8 -> 7200 | K18: TB_ELCC_SE3_SE4_01
C19: UP | D19: CAP_BND | E19: 2050 | G19: ='Data New Transmission'!Z7 -> 8910 | H19: ='Data New Transmission'!Z7 -> 8910 | K19: TB_ELCC_SE2_SE3_01
D20: AFA | F20: 1 | G20: =F20 -> 1 | H20: =F20 -> 1 | I20: =F20 -> 1 | K20: TB_ELCC_SE1_SE2_01
D21: AFA | F21: 1 | G21: =F21 -> 1 | H21: =F21 -> 1 | I21: =F21 -> 1 | K21: TB_ELCC_SE2_SE3_01
D22: AFA | F22: 1 | G22: =F22 -> 1 | H22: =F22 -> 1 | I22: =F22 -> 1 | K22: TB_ELCC_SE3_SE4_01
D23: CAP2ACT | F23: 0.031536 | G23: =F23 -> 0.031536 | H23: =F23 -> 0.031536 | I23: =F23 -> 0.031536 | K23: TB_ELCC_SE1_SE2_01
D24: CAP2ACT | F24: 0.031536 | G24: =F24 -> 0.031536 | H24: =F24 -> 0.031536 | I24: =F24 -> 0.031536 | K24: TB_ELCC_SE2_SE3_01
D25: CAP2ACT | F25: 0.031536 | G25: =F25 -> 0.031536 | H25: =F25 -> 0.031536 | I25: =F25 -> 0.031536 | K25: TB_ELCC_SE3_SE4_01
D26: LIFE | F26: 50 | G26: =F26 -> 50 | H26: =F26 -> 50 | I26: =F26 -> 50 | K26: TB_ELCC_SE1_SE2_01
D27: LIFE | F27: 50 | G27: =F27 -> 50 | H27: =F27 -> 50 | I27: =F27 -> 50 | K27: TB_ELCC_SE2_SE3_01
D28: LIFE | F28: 50 | G28: =F28 -> 50 | H28: =F28 -> 50 | I28: =F28 -> 50 | K28: TB_ELCC_SE3_SE4_01
D29: INVCOST | F29: ='Data New Transmission'!W14 -> 0.29 | G29: =F29 -> 0.29 | H29: =F29 -> 0.29 | I29: =F29 -> 0.29 | K29: TB_ELCC_SE1_SE2_01
D30: INVCOST | F30: ='Data New Transmission'!W14 -> 0.29 | G30: =F30 -> 0.29 | H30: =F30 -> 0.29 | I30: =F30 -> 0.29 | K30: TB_ELCC_SE2_SE3_01
D31: INVCOST | F31: ='Data New Transmission'!W14 -> 0.29 | G31: =F31 -> 0.29 | H31: =F31 -> 0.29 | I31: =F31 -> 0.29 | K31: TB_ELCC_SE3_SE4_01
B35: EXAMPLE FROM NORDPOOL MODEL
B37: TimeSlice | C37: LimType | D37: Attribute | E37: Year | F37: AllRegions | K37: NOR | L37: FIN | M37: SWE | N37: Pset_Set | O37: Pset_PN | P37: Pset_PD | Q37: Pset_CI | R37: Pset_CO | S37: Cset_Set | T37: Cset_CN | U37: Cset_CD
D38: EFF | E38: 2010 | F38: 0.97 | O38: TB_ELCC*
D39: AFA | F39: 0.95 | O39: TB_ELCC*
D40: CAP2ACT | F40: 0.031536 | O40: TB_ELCC*
C41: UP | D41: CAP_BND | E41: 0 | F41: 5 | O41: TB_ELCC*
C42: UP | D42: CAP_BND | E42: 2010 | K42: 3600 | M42: 3600 | O42: TB_ELCC_NOR_SWE_01
C43: UP | D43: CAP_BND | E43: 2010 | K43: 70 | L43: 100 | O43: TB_ELCC_NOR_FIN_01
C44: UP | D44: CAP_BND | E44: 2010 | L44: 1650 | M44: 2050 | O44: TB_ELCC_FIN_SWE_01
...

Sheet Sheet1
B3: FROM: Elåret 2014, S

Sheet Data New Transmission
B1: From NETP 2016 Ch. 3 pp. 166
Y2: In 2030 | Z2: 2030-2050
X3: Existing | Y3: Capacity | Z3: Capacity | AA3: Invest | AB3: Invest
X4: MW | Y4: MW | Z4: Total MW | AA4: Meuros 2014/MW | AB4: MDKK 2014/MW
V5: From | W5: To
V6: SE1 | W6: SE2 | X6: 3300 | Y6: 3300 | Z6: 3300 | AA6: 0.58
V7: SE2 | W7: SE3 | X7: 7300 | Y7: 8700 | Z7: =Y7+210 -> 8910 | AA7: 0.58
V8: SE3 | W8: SE4 | X8: 5300 and 2000 | Y8: 7200 | Z8: =Y8 -> 7200 | AA8: 0.58
W11: Cost allocation
W12: SE1 | X12: SE2 | Y12: SE3 | Z12: SE4
W13: Meuros 2014/MW
W14: =AA6/2 -> 0.29 | X14: =W14 -> 0.29 | Y14: =W14 -> 0.29 | Z14: =W14 -> 0.29

Sheet Data Existing Transmission
B2: Picture from: TIMES-NO documentaiton (Pernille) pp. 4. the picture is probably referring to the situation in 2012. | M2: Picture from: "Nordic Market report 2013" by NordReg, pp. 20. It is placed in the folder called "My Data"
AC3: Existing Lines
AC4: Agora Study - "Increased Integration of the Nordic and German Electricity Systems" pp. 154
B38: Picture Extracted from the "Data" excel workbook which embodied the Flex4RES database for their base year (2012). The picture is contained in the sheet called "35".
